[2023-06-25T02:22:03.821+0000] {taskinstance.py:1103} INFO - Dependencies all met for dep_context=non-requeueable deps ti=<TaskInstance: my_dag.choose_best_model manual__2023-06-25T02:20:51.045539+00:00 [queued]>
[2023-06-25T02:22:04.058+0000] {taskinstance.py:1103} INFO - Dependencies all met for dep_context=requeueable deps ti=<TaskInstance: my_dag.choose_best_model manual__2023-06-25T02:20:51.045539+00:00 [queued]>
[2023-06-25T02:22:04.066+0000] {taskinstance.py:1308} INFO - Starting attempt 1 of 1
[2023-06-25T02:22:04.482+0000] {taskinstance.py:1327} INFO - Executing <Task(BranchPythonOperator): choose_best_model> on 2023-06-25 02:20:51.045539+00:00
[2023-06-25T02:22:04.570+0000] {standard_task_runner.py:57} INFO - Started process 562 to run task
[2023-06-25T02:22:04.709+0000] {standard_task_runner.py:84} INFO - Running: ['***', 'tasks', 'run', 'my_dag', 'choose_best_model', 'manual__2023-06-25T02:20:51.045539+00:00', '--job-id', '10', '--raw', '--subdir', 'DAGS_FOLDER/my_dag.py', '--cfg-path', '/tmp/tmpsoua48sj']
[2023-06-25T02:22:04.779+0000] {standard_task_runner.py:85} INFO - Job 10: Subtask choose_best_model
[2023-06-25T02:22:05.343+0000] {task_command.py:410} INFO - Running <TaskInstance: my_dag.choose_best_model manual__2023-06-25T02:20:51.045539+00:00 [running]> on host 8b092f32fb5b
[2023-06-25T02:22:06.214+0000] {taskinstance.py:1547} INFO - Exporting env vars: AIRFLOW_CTX_DAG_OWNER='***' AIRFLOW_CTX_DAG_ID='my_dag' AIRFLOW_CTX_TASK_ID='choose_best_model' AIRFLOW_CTX_EXECUTION_DATE='2023-06-25T02:20:51.045539+00:00' AIRFLOW_CTX_TRY_NUMBER='1' AIRFLOW_CTX_DAG_RUN_ID='manual__2023-06-25T02:20:51.045539+00:00'
[2023-06-25T02:22:06.290+0000] {taskinstance.py:1824} ERROR - Task failed with exception
Traceback (most recent call last):
  File "/home/airflow/.local/lib/python3.7/site-packages/airflow/operators/python.py", line 215, in execute
    branch = super().execute(context)
  File "/home/airflow/.local/lib/python3.7/site-packages/airflow/operators/python.py", line 181, in execute
    return_value = self.execute_callable()
  File "/home/airflow/.local/lib/python3.7/site-packages/airflow/operators/python.py", line 198, in execute_callable
    return self.python_callable(*self.op_args, **self.op_kwargs)
  File "/opt/airflow/dags/my_dag.py", line 17, in _choose_best_model
    if (best_accuracy > 8):
NameError: name 'best_accuracy' is not defined
[2023-06-25T02:22:06.336+0000] {taskinstance.py:1350} INFO - Marking task as FAILED. dag_id=my_dag, task_id=choose_best_model, execution_date=20230625T022051, start_date=20230625T022203, end_date=20230625T022206
[2023-06-25T02:22:06.428+0000] {standard_task_runner.py:109} ERROR - Failed to execute job 10 for task choose_best_model (name 'best_accuracy' is not defined; 562)
[2023-06-25T02:22:06.547+0000] {local_task_job_runner.py:225} INFO - Task exited with return code 1
[2023-06-25T02:22:06.847+0000] {taskinstance.py:2653} INFO - 0 downstream tasks scheduled from follow-on schedule check
