[2023-06-26T01:48:52.578+0000] {taskinstance.py:1103} INFO - Dependencies all met for dep_context=non-requeueable deps ti=<TaskInstance: my_dag.get_seed_df manual__2023-06-26T01:48:05.186200+00:00 [queued]>
[2023-06-26T01:48:53.044+0000] {taskinstance.py:1103} INFO - Dependencies all met for dep_context=requeueable deps ti=<TaskInstance: my_dag.get_seed_df manual__2023-06-26T01:48:05.186200+00:00 [queued]>
[2023-06-26T01:48:53.067+0000] {taskinstance.py:1308} INFO - Starting attempt 1 of 1
[2023-06-26T01:48:53.374+0000] {taskinstance.py:1327} INFO - Executing <Task(PythonOperator): get_seed_df> on 2023-06-26 01:48:05.186200+00:00
[2023-06-26T01:48:53.431+0000] {standard_task_runner.py:57} INFO - Started process 278 to run task
[2023-06-26T01:48:54.308+0000] {standard_task_runner.py:84} INFO - Running: ['***', 'tasks', 'run', 'my_dag', 'get_seed_df', 'manual__2023-06-26T01:48:05.186200+00:00', '--job-id', '44', '--raw', '--subdir', 'DAGS_FOLDER/my_dag.py', '--cfg-path', '/tmp/tmp29dlz1ne']
[2023-06-26T01:48:54.459+0000] {standard_task_runner.py:85} INFO - Job 44: Subtask get_seed_df
[2023-06-26T01:48:58.513+0000] {task_command.py:410} INFO - Running <TaskInstance: my_dag.get_seed_df manual__2023-06-26T01:48:05.186200+00:00 [running]> on host 414be138234a
[2023-06-26T01:49:04.645+0000] {taskinstance.py:1547} INFO - Exporting env vars: AIRFLOW_CTX_DAG_OWNER='***' AIRFLOW_CTX_DAG_ID='my_dag' AIRFLOW_CTX_TASK_ID='get_seed_df' AIRFLOW_CTX_EXECUTION_DATE='2023-06-26T01:48:05.186200+00:00' AIRFLOW_CTX_TRY_NUMBER='1' AIRFLOW_CTX_DAG_RUN_ID='manual__2023-06-26T01:48:05.186200+00:00'
[2023-06-26T01:49:04.653+0000] {taskinstance.py:1824} ERROR - Task failed with exception
Traceback (most recent call last):
  File "/home/airflow/.local/lib/python3.7/site-packages/airflow/operators/python.py", line 181, in execute
    return_value = self.execute_callable()
  File "/home/airflow/.local/lib/python3.7/site-packages/airflow/operators/python.py", line 198, in execute_callable
    return self.python_callable(*self.op_args, **self.op_kwargs)
  File "/opt/airflow/dags/my_dag.py", line 14, in get_seed_df
    df = get_big_query(query)
  File "/opt/airflow/dags/lib/big_query_access.py", line 5, in get_big_query
    credentials = service_account.Credentials.from_service_account_file(credientials_path)
  File "/home/airflow/.local/lib/python3.7/site-packages/google/oauth2/service_account.py", line 257, in from_service_account_file
    filename, require=["client_email", "token_uri"]
  File "/home/airflow/.local/lib/python3.7/site-packages/google/auth/_service_account_info.py", line 80, in from_filename
    with io.open(filename, "r", encoding="utf-8") as json_file:
FileNotFoundError: [Errno 2] No such file or directory: './oceanic-variety-386313-5611c0e63164.json'
[2023-06-26T01:49:05.126+0000] {taskinstance.py:1350} INFO - Marking task as FAILED. dag_id=my_dag, task_id=get_seed_df, execution_date=20230626T014805, start_date=20230626T014852, end_date=20230626T014905
[2023-06-26T01:49:05.757+0000] {standard_task_runner.py:109} ERROR - Failed to execute job 44 for task get_seed_df ([Errno 2] No such file or directory: './oceanic-variety-386313-5611c0e63164.json'; 278)
[2023-06-26T01:49:06.353+0000] {local_task_job_runner.py:225} INFO - Task exited with return code 1
[2023-06-26T01:49:07.430+0000] {taskinstance.py:2653} INFO - 0 downstream tasks scheduled from follow-on schedule check
